<?xml version='1.0'?>

<robot name="mome" xmlns:xacro="http://www.ros.org/wiki/xacro">
    <xacro:property name="robot_name" value="mome" />
    <xacro:property name="robot_chassis_mass" value="15"/>
    <xacro:property name="robot_chassis_length" value="0.2"/>
    <xacro:property name="robot_chassis_radius" value="0.25"/>
    <xacro:property name="robot_caster_wheel_radius" value="0.05"/>
    <xacro:property name="robot_caster_wheel_radius_collision" value="0.0499"/>

    <xacro:property name="robot_wheel_mass" value="5"/>
    <xacro:property name="robot_wheel_length" value="0.05"/>
    <xacro:property name="robot_wheel_radius" value="0.1"/>

    <xacro:property name="camera_mass" value="0.1"/>

    <!-- Lidar properties -->
    <xacro:property name="lidar_samples" value="720"/>
    <xacro:property name="lidar_resolution" value="1.0"/>
    <xacro:property name="lidar_range" value="30.0"/>

    <!-- Project center to the ground -->
    <link name="dummy"></link>

    <!-- Make Chassis of Bot -->
    <link name="body_link">
        <pose>0 0 0.1 0 0 0</pose>
        <inertial>
        <mass value="${robot_chassis_mass}"/>
        <origin xyz="0.0 0 0" rpy=" 0 0 0"/>
        <inertia 
            ixx="0.147116667" ixy="0" ixz="0"
            iyy="0.334951167" iyz="0"
            izz="0.3978345"
        />
        </inertial>

        <collision name="collision">
            <origin xyz="0 0 0.05" rpy=" 0 0 0"/>
            <geometry>
                <box size="0.5 0.5 0.2"/>
            </geometry>
        </collision>

        <visual name="chassis_visual">
            <origin xyz="0 0 0.05" rpy=" 0 0 0"/>
            <geometry>
                <box size="0.5 0.5 0.2"/>
            </geometry>
        </visual>
  </link>

  <!-- Right Wheel Back -->
  <link name="wheel2_link">
    <inertial>
      <mass value="${robot_wheel_mass}"/>
      <origin xyz="0 0 0" rpy="0 1.5707 1.5707"/>
      <inertia
        ixx="0.1" ixy="0.0" ixz="0.0"
        iyy="0.1" iyz="0.0"
        izz="0.1"
      />
    </inertial>

    <visual>
      <origin xyz="0 0 0" rpy="0 1.5707 1.5707"/>
      <geometry>
        <cylinder radius="${robot_wheel_radius}" length="${robot_wheel_length}"/>
      </geometry>
    </visual>

    <collision>
      <origin xyz="0 0 0" rpy="0 1.5707 1.5707"/>
      <geometry>
        <cylinder radius="${robot_wheel_radius}" length="${robot_wheel_length}"/>
      </geometry>
    </collision>

  </link>

  <!-- Right Wheel Front-->
  <link name="wheel4_link">
    <inertial>
      <mass value="${robot_wheel_mass}"/>
      <origin xyz="0 0 0" rpy="0 1.5707 1.5707"/>
      <inertia
        ixx="0.1" ixy="0.0" ixz="0.0"
        iyy="0.1" iyz="0.0"
        izz="0.1"
      />
    </inertial>

    <visual>
      <origin xyz="0 0 0" rpy="0 1.5707 1.5707"/>
      <geometry>
        <cylinder radius="${robot_wheel_radius}" length="${robot_wheel_length}"/>
      </geometry>
    </visual>

    <collision>
      <origin xyz="0 0 0" rpy="0 1.5707 1.5707"/>
      <geometry>
        <cylinder radius="${robot_wheel_radius}" length="${robot_wheel_length}"/>
      </geometry>
    </collision>

  </link>

  <!-- Left wheel Back-->
  <link name="wheel1_link">
    <inertial>
      <mass value="${robot_wheel_mass}"/>
      <origin xyz="0 0 0" rpy="0 1.5707 1.5707"/>
      <inertia
        ixx="0.1" ixy="0.0" ixz="0.0"
        iyy="0.1" iyz="0.0"
        izz="0.1"
      />
    </inertial>

    <visual>
      <origin xyz="0 0 0" rpy="0 1.5707 1.5707"/>
      <geometry>
        <cylinder radius="${robot_wheel_radius}" length="${robot_wheel_length}"/>
      </geometry>
    </visual>

    <collision>
      <origin xyz="0 0 0" rpy="0 1.5707 1.5707"/>
      <geometry>
        <cylinder radius="${robot_wheel_radius}" length="${robot_wheel_length}"/>
      </geometry>
    </collision>

  </link>

  <!-- Left wheel Front-->
  <link name="wheel3_link">
    <inertial>
      <mass value="${robot_wheel_mass}"/>
      <origin xyz="0 0 0" rpy="0 1.5707 1.5707"/>
      <inertia
        ixx="0.1" ixy="0.0" ixz="0.0"
        iyy="0.1" iyz="0.0"
        izz="0.1"
      />
    </inertial>

    <visual>
      <origin xyz="0 0 0" rpy="0 1.5707 1.5707"/>
      <geometry>
        <cylinder radius="${robot_wheel_radius}" length="${robot_wheel_length}"/>
      </geometry>
    </visual>

    <collision>
      <origin xyz="0 0 0" rpy="0 1.5707 1.5707"/>
      <geometry>
        <cylinder radius="${robot_wheel_radius}" length="${robot_wheel_length}"/>
      </geometry>
    </collision>

  </link>

  <!-- Camera -->
  <link name="camera_link">
    <inertial>
      <mass value="${camera_mass}"/>
      <origin xyz="0 0 0" rpy="0 0 0"/>
      <inertia
        ixx="1e-6" ixy="0.0" ixz="0.0"
        iyy="1e-6" iyz="0.0"
        izz="1e-6"
      />
    </inertial>

    <visual>
      <origin xyz="0 0 0" rpy="0 0 0"/>
      <geometry>
        <box size="0.05 0.05 0.05"/>
      </geometry>
    </visual>

    <collision>
      <origin xyz="0 0 0" rpy="0 0 0"/>
      <geometry>
        <box size="0.05 0.05 0.05"/>
      </geometry>
    </collision>
  </link>

  <link name="lidar_link">
        <visual>
            <geometry>
                <cylinder length="0.04" radius="0.02"/>
            </geometry>
            <origin rpy="0 0 0" xyz="0 0 0"/>
        </visual>
        <sensor type="ray" name="lidar">
            <ray>
                <scan>
                    <horizontal>
                        <samples>${lidar_samples}</samples>
                        <resolution>${lidar_resolution}</resolution>
                        <min_angle>-1.5708</min_angle>
                        <max_angle>1.5708</max_angle>
                    </horizontal>
                </scan>
                <range>
                    <min>0.0</min>
                    <max>${lidar_range}</max>
                </range>
            </ray>
            <plugin name="lidar_controller" filename="libgazebo_ros_laser.so"/>
        </sensor>
    </link>

    <!-- Define Joints -->
    <!-- Joint for base to the ground -->
    <joint type="fixed" name="dummy_joint">
        <parent link="dummy"/>
        <child link="body_link"/>
        <origin xyz="0 0 0" rpy="0 0 0" />
    </joint>

    <!-- Right Wheel Joint Back-->
    <joint type="continuous" name="wheel2_joint">
        <origin xyz="-0.2 -0.30 0" rpy="0 0 0" />
        <parent link="body_link"/>
        <child link="wheel2_link"/>
        <axis xyz="0 1 0"/>
    </joint>

    <!-- Right Wheel Joint Front-->
    <joint type="continuous" name="wheel4_joint">
        <origin xyz="0.2 -0.30 0" rpy="0 0 0" />
        <parent link="body_link"/>
        <child link="wheel4_link"/>
        <axis xyz="0 1 0"/>
    </joint>

    <!-- Left Wheel Joint Back-->
    <joint type="continuous" name="wheel1_joint">
        <origin xyz="-0.2 0.30 0" rpy="0 0 0" />
        <parent link="body_link"/>
        <child link="wheel1_link"/>
        <axis xyz="0 1 0"/>
    </joint>

    <!-- Left Wheel Joint Front-->
    <joint type="continuous" name="wheel3_joint">
        <origin xyz="0.2 0.30 0" rpy="0 0 0" />
        <parent link="body_link"/>
        <child link="wheel3_link"/>
        <axis xyz="0 1 0"/>
    </joint>

    <!-- Camera Joint -->
    <joint name="camera_joint" type="fixed">
        <origin xyz="0.25 0 0.08" rpy="0 0 0"/>
        <parent link="body_link"/>
        <child link="camera_link"/>
    </joint>

    <joint name="lidar_joint" type="fixed">
        <parent link="body_link"/>
        <child link="lidar_link"/>
        <origin xyz="0.25 0 0.16" rpy="0 0 0"/>  
    </joint>

	<!-- Motor, Camera and Lidar Simulation -->
	<xacro:include filename="$(find mome)/urdf/mome.gazebo" />
</robot>
